const PENDING = "pending";
const FULFILLED = "fulfilled";
const REJECTED = "rejected";

class MyPromise {
  constructor(executor) {
    try {
      executor(this.resolve, this.reject);
    } catch (e) {
      this.reject(e);
    }
  }
  // promise状态
  status = PENDING;
  // 成功之后的值
  value = undefined;
  // 失败后的原因
  reason = undefined;
  // 成功回调
  successCallback = [];
  // 失败回调
  failCallback = [];

  // 把resolve和reject用箭头函数写，使this指向promise的实例对象
  resolve = (value) => {
    if (this.status !== PENDING) return;
    // 将状态更改为成功
    this.status = FULFILLED;
    // 保存成功之后的值
    this.value = value;
    // 判断成功回调是否存在，如果存在 调用
    while (this.successCallback.length) this.successCallback.shift()();
  };
  reject = (reason) => {
    if (this.status !== PENDING) return;
    this.status = REJECTED;
    // 保存失败后的原因
    this.reason = reason;
    while (this.failCallback.length) this.failCallback.shift()();
  };
  then(successCallback, failCallback) {
    successCallback = successCallback ? successCallback : (value) => value;
    failCallback = failCallback
      ? failCallback
      : (reason) => {
          throw reason;
        };
    let promise2 = new MyPromise((resolve, reject) => {
      if (this.status === FULFILLED) {
        setTimeout(() => {
          try {
            let x = successCallback(this.value);
            resolvePromise(promise2, x, resolve, reject);
          } catch (e) {
            reject(e);
          }
        }, 0);
      } else if (this.status === REJECTED) {
        setTimeout(() => {
          try {
            let x = failCallback(this.reason);
            resolvePromise(promise2, x, resolve, reject);
          } catch (e) {
            reject(e);
          }
        }, 0);
      } else {
        // 等待
        // 将成功回调和失败回调存储
        this.successCallback.push(() => {
          setTimeout(() => {
            try {
              let x = successCallback(this.value);
              resolvePromise(promise2, x, resolve, reject);
            } catch (e) {
              reject(e);
            }
          }, 0);
        });
        this.failCallback.push(() => {
          setTimeout(() => {
            try {
              let x = failCallback(this.reason);
              resolvePromise(promise2, x, resolve, reject);
            } catch (e) {
              reject(e);
            }
          }, 0);
        });
      }
    });
    return promise2;
  }
  static all(array) {
    let result = [];
    let index = 0;

    return new MyPromise((resolve, reject) => {
      function addData(key, value) {
        result[key] = value;
        index++;
        if (index === array.length) {
          resolve(result);
        }
      }
      for (let i = 0; i < array.length; i++) {
        let current = array[i];
        if (current instanceof MyPromise) {
          // promise对象
          current.then(
            (value) => addData(i, value),
            (reason) => reject(reason)
          );
        } else {
          // 普通值
          addData(i, array[i]);
        }
      }
    });
  }
  static resolve(value) {
    if (value instanceof MyPromise) return value;
    return new MyPromise((resolve) => resolve(value));
  }
}

function resolvePromise(promise2, x, resolve, reject) {
  if (promise2 === x) {
    // 返回了自己
    return reject(
      new TypeError("Chaining cycle detected for promise #<Promise>")
    );
  }
  if (x instanceof MyPromise) {
    // 下面两种方法均可
    // x.then(
    //   (value) => resolve(value),
    //   (reason) => reject(reason)
    // );
    x.then(resolve, reject);
  } else {
    // 普通值
    resolve(x);
  }
}
module.exports = MyPromise;
